Workbook

Sheet 대시보드
A1: 구분 | B1: 등록 | C1: 게재 | D1: 게재율 | E1: 조회수 | G1: 통계 항목 | H1: 값
A2: 플랫폼서비스 | B2: =counta('플랫폼서비스'!D:D)-counta('플랫폼서비스'!E:E) -> 12 | C2: =counta('플랫폼서비스'!A:A)-1 -> 0 | D2: =C2/B2 -> 0 | E2: =sum('플랫폼서비스'!G:G) -> 129602 | G2: 등록 | H2: =sum(B:B) -> 1511
A3: 정부기관 | B3: =counta('정부기관'!D:D)-counta('정부기관'!E:E) -> 3 | C3: =counta('정부기관'!A:A)-1 -> 0 | D3: =C3/B3 -> 0 | E3: 148 | G3: 게재 | H3: =sum(C:C) -> 0
A4: 공모전 | B4: =counta('공모전'!D:D)-counta('공모전'!E:E) -> 23 | C4: =counta('공모전'!A:A)-1 -> 0 | D4: =C4/B4 -> 0 | E4: =sum('공모전'!G:G) -> 37980 | G4: 게재율 | H4: =H3/H2 -> 0
A5: 포털카페 | B5: =counta('포털카페'!D:D)-counta('포털카페'!E:E) -> 116 | C5: =counta('포털카페'!A:A)-1 -> 0 | D5: =C5/B5 -> 0 | E5: =sum('포털카페'!G:G) -> 509 | G5: 조회수 | H5: =sum(E:E) -> 342030
A6: SNS그룹 | B6: =counta('SNS그룹'!D:D)-counta('SNS그룹'!E:E) -> 92 | C6: =counta('SNS그룹'!A:A)-1 -> 0 | D6: =C6/B6 -> 0 | E6: =sum('SNS그룹'!G:G) -> 11
A7: 커뮤니티 | B7: =counta('커뮤니티'!D:D)-counta('커뮤니티'!E:E) -> 25 | C7: =counta('커뮤니티'!A:A)-1 -> 0 | D7: =C7/B7 -> 0 | E7: =sum('커뮤니티'!G:G) -> 2619
A8: 오픈단톡방 | B8: =counta('오픈단톡방'!D:D)-counta('오픈단톡방'!E:E) -> 22 | C8: =counta('오픈단톡방'!A:A)-1 -> 0 | D8: =C8/B8 -> 0 | E8: =sum('오픈단톡방'!G:G) -> 0
A9: 디스코드 | B9: =counta('디스코드'!D:D)-counta('디스코드'!E:E) -> 4 | C9: =counta('디스코드'!A:A)-1 -> 0 | D9: =C9/B9 -> 0 | E9: =sum('디스코드'!G:G) -> 0
A10: 대학원공문 | B10: =counta('대학원공문'!D:D)-counta('대학원공문'!E:E) -> 117 | C10: =counta('대학원공문'!A:A)-1 -> 0 | D10: =C10/B10 -> 0 | E10: =sum('대학원공문'!G:G) -> 0
A11: 대학교공문 | B11: =counta('대학교공문'!D:D)-counta('대학교공문'!E:E) -> 229 | C11: =counta('대학교공문'!A:A)-1 -> 0 | D11: =C11/B11 -> 0 | E11: =sum('대학교공문'!F:F) -> 0
A12: 고등학교공문 | B12: =counta('고등학교공문'!D:D)-counta('고등학교공문'!E:E) -> 1 | C12: =counta('고등학교공문'!A:A)-1 -> 0 | D12: =C12/B12 -> 0 | E12: =sum('고등학교공문'!F:F) -> 0
A13: 기관공문 | B13: =counta('기관공문'!D:D)-counta('기관공문'!E:E) -> 2 | C13: =counta('고등학교공문'!A:A)-1 -> 0 | D13: =C13/B13 -> 0 | E13: =sum('고등학교공문'!F:F) -> 0
A14: DM-학회 | B14: =counta('DM-학회'!D:D)-counta('DM-학회'!E:E) -> 9 | C14: =counta('DM-대학'!A:A)-1 -> 0 | D14: =C14/B14 -> 0 | E14: =sum('DM-대학'!F:F) -> 0
A15: DM-협회 | B15: =counta('DM-협회'!D:D)-counta('DM-협회'!E:E) -> 47 | C15: =counta('DM-대학'!A:A)-1 -> 0 | D15: =C15/B15 -> 0 | E15: =sum('DM-대학'!F:F) -> 0
A16: DM-대학 | B16: =counta('DM-대학'!D:D)-counta('DM-대학'!E:E) -> 314 | C16: =counta('DM-대학'!A:A)-1 -> 0 | D16: =C16/B16 -> 0 | E16: =sum('DM-대학'!F:F) -> 0
A17: 옥외광고-대학 | B17: =counta('옥외광고-대학'!D:D)-counta('옥외광고-대학'!E:E) -> 231 | C17: =counta('옥외광고-대학'!A:A)-1 -> 0 | D17: =C17/B17 -> 0 | E17: =sum('고등학교공문'!F:F) -> 0
A18: 옥외광고-출연연NST | B18: =counta('옥외광고-출연연NST'!D:D)-counta('옥외광고-출연연NST'!E:E) -> 23 | C18: =counta('옥외광고-대학'!A:A)-1 -> 0 | D18: =C18/B18 -> 0 | E18: =sum('고등학교공문'!F:F) -> 0
A19: 옥외광고-대학 | B19: =counta('옥외광고-대학'!D:D)-counta('옥외광고-대학'!E:E) -> 231 | C19: =counta('옥외광고-출연연NST'!A:A)-1 -> 0 | D19: =C19/B19 -> 0 | E19: =sum('고등학교공문'!F:F) -> 0
A20: 옥외광고-협력기관 | B20: =counta('옥외광고-협력기관'!D:D)-counta('옥외광고-협력기관'!E:E) -> 7 | C20: =counta('옥외광고-협력기관'!A:A)-1 -> 0 | D20: =C20/B20 -> 0 | E20: =sum('고등학교공문'!F:F) -> 0
A21: 퍼포먼스 | B21: =counta('퍼포먼스'!D:D)-counta('퍼포먼스'!E:E) -> 1 | C21: =counta('퍼포먼스'!A:A)-1 -> 0 | D21: =C21/B21 -> 0 | E21: 171161
A22: 이벤트사이트 | B22: =counta('이벤트사이트'!D:D)-counta('이벤트사이트'!E:E) -> 2 | C22: =counta('이벤트사이트'!A:A)-1 -> 0 | D22: =C22/B22 -> 0 | E22: =sum('이벤트사이트'!F:F) -> 0

Sheet 플랫폼서비스
A1: 게재일 | B1: 이름 | C1: 회원수 | D1: 등록일 | E1: 삭제일 | F1: 주소 | G1: 조회수 | H1: 결과 | I1: 메모
B2: 태스크 | C2: 1077 | D2: 2025. 1. 1. | F2: https://aifactory.space/task/9197/overview | G2: 123674 | H2: https://aifactory.space/task/9197/overview
B3: 사전설명회 - 온라인 | C3: 1800 | D3: 2025. 1. 1. | F3: https://www.youtube.com/watch?v=mFDCHinLJ9k | G3: 2300 | H3: https://www.youtube.com/watch?v=mFDCHinLJ9k
B4: 사전설명회 - 오프라인
B5: 회원 메일링 | C5: 3628 | D5: 2025. 1. 1. | G5: 3628
B6: 배너 | D6: 2025. 1. 1. | H6: https://aifactory.space/
B7: 팝업창 | D7: 2025. 1. 1. | H7: https://aifactory.space/
B8: 유튜브 - 티저영상 | D8: 2025. 1. 1.
B9: 페이스북 페이지 (카드뉴스) | D9: 2025. 1. 1. | F9: https://www.facebook.com/aifactory.space | H9: https://www.facebook.com/aifactory.space
B10: 인스타그램 (카드뉴스) | D10: 45968
B11: 스레드 (카드뉴스) | D11: 2025. 1. 1.
B12: X (구 트위터) (카드뉴스) | D12: 2025. 1. 1.
B13: 보도자료 - 개최 | D13: 2025. 1. 1.
B14: 보도자료 - 종료 | D14: 2025. 1. 1.

Sheet 정부기관
A1: 게재일 | B1: 이름 | C1: 회원수 | D1: 등록일 | E1: 삭제일 | F1: 주소 | G1: 조회수 | H1: 결과 | I1: 메모
B2: 소통24 | D2: 2025. 9. 1. | F2: https://sotong.go.kr | G2: 148 | H2: https://sotong.go.kr/front/epilogue/epilogueNewViewPage.do?bbs_id=109685c9417242ff94e9401c7b34a880&pagetype=bbs&search_result=&search_result_cnddt=&epilogue_bgnde=&epilogue_endde=&date_range=all&epilogue_bgnde_cnddt=&epilogue_endde_cnddt=&date_range_cnddt=all&search_title_contents=&search_insttNm=&miv_pageNo=1&preDate=&endDate=
B3: 온나라 | D3: 2025. 9. 1.
B4: 행정안전부 하모니 | D4: 2025. 9. 1.

Sheet 공모전
A1: 게재일 | B1: 이름 | C1: 회원수 | D1: 등록일 | E1: 삭제일 | F1: 주소 | G1: 조회수 | H1: 결과 | I1: 메모
B2: 스펙토리 | D2: 2025. 1. 1. | F2: https://www.spectory.net/contest/share?uid=56460 | H2: https://www.spectory.net/contest/share?uid=56460
B3: 씽굿 | D3: 2025. 1. 1. | F3: https://www.thinkcontest.com/thinkgood/user/educate/view.do?querystr=rSW3rryZv7-Ml0u2sExn_IEyKBxQFlYA4cseY26X3X8 | G3: 53 | H3: https://www.thinkcontest.com/thinkgood/user/educate/view.do?querystr=rSW3rryZv7-Ml0u2sExn_IEyKBxQFlYA4cseY26X3X8
B4: 씽유 | D4: 2025. 1. 1. | F4: https://thinkyou.co.kr/contest/sector_view.asp?idx=58274 | G4: 2175 | H4: https://thinkyou.co.kr/contest/sector_view.asp?idx=58274
B5: 온오프믹스 | D5: 2025. 1. 1. | F5: https://onoffmix.com/event/331962 | G5: 0 | H5: https://onoffmix.com/event/331962
B6: 올콘 | D6: 2025. 1. 1. | F6: https://www.all-con.co.kr/view/contest/530626?page=1&sortname=cl_order&sortorder=asc&stx=%EB%94%A5%ED%8E%98%EC%9D%B4%ED%81%AC | G6: 1125 | H6: https://www.all-con.co.kr/view/contest/530626?page=1&sortname=cl_order&sortorder=asc&stx=%EB%94%A5%ED%8E%98%EC%9D%B4%ED%81%AC
B7: 요즘것들 | D7: 2025. 1. 1. | F7: https://www.allforyoung.com/posts/72178 | G7: 0 | H7: https://www.allforyoung.com/posts/72178
B8: 이벤터스 | D8: 2025. 1. 1. | F8: https://event-us.kr/maycan/event/113610 | G8: 0 | H8: https://event-us.kr/maycan/event/113610
B9: 인크루트 | D9: 2025. 1. 1. | F9: https://gongmo.incruit.com/info/gongmolistinfo.asp?contestno=202509300000 | G9: 156 | H9: https://gongmo.incruit.com/info/gongmolistinfo.asp?contestno=202509300000
B10: 공모전알고 | D10: 2025. 1. 1. | F10: https://www.contestalgo.com/sub/contest_view.php?num=8008 | G10: 926 | H10: https://www.contestalgo.com/sub/contest_view.php?num=8295
B11: 공모탑 | C11: 13 | D11: 2025. 1. 1. | F11: https://www.gongmotop.com/bbs/board.php?bo_table=b0101&wr_id=8305 | G11: 11 | H11: https://www.gongmotop.com/bbs/board.php?bo_table=b0101&wr_id=8579
B12: 대티즌 | D12: 2025. 1. 1. | F12: https://www.detizen.com/contest/view/0/6899aba8452ce905d1fa77e6 | J12: 게시대기중
B13: 더콘테스트 | D13: 2025. 1. 1. | I13: 홈페이지접속불가
B14: 데모데이 | C14: 21 | D14: 2025. 1. 1. | F14: http://www.demoday.co.kr/community/event/3294 | G14: 279 | H14: http://www.demoday.co.kr/community/event/3399
B15: 링커리어(Linkareer) | C15: 297 | D15: 2025. 1. 1. | F15: https://linkareer.com/activity/254347 | G15: 503 | H15: https://linkareer.com/activity/276040
B16: 슈퍼루키 | D16: 2025. 1. 1. | F16: https://www.superookie.com/activities/686f4457034fab484a66df6a
B17: 스팩토리 | D17: 2025. 1. 1. | F17: https://www.spectory.net/search/results?searchTxt=%EC%9D%B8%EA%B3%B5%EC%A7%80%EB%8A%A5 | H17: https://www.spectory.net/pages/mypage/manager
B18: 위비티 | D18: 2025. 1. 1. | F18: https://www.wevity.com/ | I18: 검토중
B19: 캠퍼즈 | D19: 2025. 1. 1. | F19: https://www.campuz.net/index.php?mid=upload_contest&document_srl=477681 | G19: 0 | H19: https://www.campuz.net/index.php?mid=upload_contest&document_srl=483411
B20: 컬처플 | D20: 2025. 1. 1. | F20: https://www.cultureple.com/?c=challenge&s=1&gp=1&ob=idx&gbn=viewok&ix=27167 | G20: 0 | H20: https://www.cultureple.com/?c=challenge&s=1&gp=1&ob=idx&gbn=viewok&ix=27301
B21: 코워커(co-worker) | C21: 6212 | D21: 2025. 1. 1. | F21: https://co-worker.co.kr/Contest/contest_view?idx=13074 | G21: 32726 | H21: https://co-worker.co.kr/Contest/contest_view?idx=13729
B22: 콘테스트 코리아 | C22: 98 | D22: 2025. 1. 1. | F22: https://www.contestkorea.com/sub/view.php?displayrow=20&int_gbn=1&Txt_key=all&Txt_word=&Txt_sortkey=a.int_sort&Txt_sortword=desc&page=1&int_gbn=1&Txt_bcode=030310001&str_no=202507100062 | I22: 검토중
B23: 패스타 | D23: 2025. 1. 1. | I23: 홈페이지리뉴얼중
B24: g콘테스트 | C24: 13 | D24: 2025. 1. 1. | F24: https://gcontest.co.kr/front/m/comp/view/26847 | G24: 26 | H24: https://gcontest.co.kr/front/m/comp/view/29880

Sheet 포털카페
A1: 게재일 | B1: 이름 | C1: 회원수 | D1: 등록일 | E1: 삭제일 | F1: 주소 | G1: 조회수 | H1: 결과 | I1: 메모
B2: 인공지능 스타트업 커뮤니티, AI startup community | D2: 2025. 9. 1. | F2: https://cafe.naver.com/2018startup/6867 | G2: 11 | H2: https://cafe.naver.com/2018startup/6867
B3: 대학홍보마케팅전문가카페 | C3: 212 | D3: 2025. 1. 1. | F3: https://cafe.naver.com/aduniv/4656 | G3: 2 | H3: https://cafe.naver.com/aduniv?iframe_url_utf8=%2FArticleRead.nhn%253Fclubid%3D17929772%2526articleid%3D4684%2526menuid%3D2%2526boardtype%3DL
B4: 폴리텍대학 대전캠퍼스전기전자제어과 인공지능 개론 | C4: 117 | D4: 2025. 1. 1. | F4: https://cafe.naver.com/ai2022/808 | G4: 2 | H4: https://cafe.naver.com/ai2022?iframe_url_utf8=%2FArticleRead.nhn%253Fclubid%3D30670410%2526articleid%3D821%2526menuid%3D1%2526boardtype%3DL
B5: 한국인공지능커뮤니티 | C5: 1005 | D5: 2025. 1. 1. | F5: https://cafe.naver.com/ai4kr/1036 | G5: 2 | H5: https://cafe.naver.com/ai4kr?iframe_url_utf8=%2FArticleRead.nhn%253Fclubid%3D30409079%2526articleid%3D1076%2526menuid%3D1%2526boardtype%3DL
B6: 인공지능을 꿈꾸는 사람들 | C6: 602 | D6: 2025. 1. 1. | F6: https://cafe.naver.com/aidreaming/768 | G6: 4 | H6: https://cafe.naver.com/aidreaming?iframe_url_utf8=%2FArticleRead.nhn%253Fclubid%3D25716140%2526articleid%3D787%2526menuid%3D5%2526boardtype%3DL
B7: AI 매니아 - 인공지능비서 네이버 대표카페 | C7: 171 | D7: 2025. 1. 1. | F7: https://cafe.naver.com/aimania/240 | G7: 6 | H7: https://cafe.naver.com/aimania?iframe_url_utf8=%2FArticleRead.nhn%253Fclubid%3D28910660%2526articleid%3D255%2526menuid%3D1%2526boardtype%3DL
B8: Artificial Intelligence Researchers | D8: 2025. 9. 1. | F8: https://cafe.naver.com/airesearchers/3413 | G8: 7 | H8: https://cafe.naver.com/airesearchers/3413
B9: 알기쉬운 정보보안기사/정보보안산업기사 | D9: 2025. 9. 1. | F9: https://cafe.naver.com/algisa/65386 | G9: 47 | H9: https://cafe.naver.com/algisa/65386
B10: 대학시절 경력쌓기 | C10: 894 | D10: 2025. 1. 1. | F10: https://cafe.naver.com/betterfuture1/5845 | G10: 1 | H10: https://cafe.naver.com/betterfuture1?iframe_url_utf8=%2FArticleRead.nhn%253Fclubid%3D17002564%2526articleid%3D5905%2526menuid%3D49%2526boardtype%3DL
B11: 선한인공지능연구소 | C11: 1837 | D11: 2025. 1. 1. | F11: https://cafe.naver.com/coyedu/38927 | G11: 1 | H11: https://cafe.naver.com/coyedu?iframe_url_utf8=%2FArticleRead.nhn%253Fclubid%3D19384686%2526articleid%3D38954%2526menuid%3D788%2526boardtype%3DL
B12: 다음 세상을 대비하는 소프트웨어 협동조합 | C12: 206 | D12: 2025. 1. 1. | F12: https://cafe.naver.com/danmuzy/2246 | G12: 1 | H12: https://cafe.naver.com/danmuzy?iframe_url_utf8=%2FArticleRead.nhn%253Fclubid%3D10660029%2526articleid%3D2259%2526menuid%3D65%2526boardtype%3DL
B13: 정보나눔대학생카페 | C13: 9536 | D13: 2025. 1. 1. | F13: https://cafe.naver.com/davidfm/82864 | G13: 1 | H13: https://cafe.naver.com/davidfm?iframe_url_utf8=%2FArticleRead.nhn%253Fclubid%3D20419340%2526articleid%3D83512%2526menuid%3D236%2526boardtype%3DL
B14: 공모전으로 취업하자! ★공모전/인턴/취업박람회★ | C14: 5211 | D14: 2025. 1. 1. | F14: https://cafe.naver.com/dcontest/54542 | G14: 2 | H14: https://cafe.naver.com/dcontest?iframe_url_utf8=%2FArticleRead.nhn%253Fclubid%3D12301611%2526articleid%3D54933%2526menuid%3D3%2526boardtype%3DL
B15: 펀디 (Fun.D) IT 프로젝트 커뮤니티 | C15: 1255 | D15: 2025. 1. 1. | F15: https://cafe.naver.com/eofl7942/2384 | G15: 2 | H15: https://cafe.naver.com/eofl7942?iframe_url_utf8=%2FArticleRead.nhn%253Fclubid%3D27607764%2526articleid%3D2502%2526menuid%3D73%2526boardtype%3DL
B16: !!공모전 으로 뚫자 !!!! 취업대란 | C16: 1970 | D16: 2025. 1. 1. | F16: https://cafe.naver.com/gongmojun/11321 | G16: 1 | H16: https://cafe.naver.com/gongmojun?iframe_url_utf8=%2FArticleRead.nhn%253Fclubid%3D10149239%2526articleid%3D11490%2526menuid%3D14%2526boardtype%3DL
B17: 정보보안저문가 취업카페 스칼라 | D17: 2025. 9. 1. | F17: https://cafe.naver.com/neteg/279548 | G17: 12 | H17: https://cafe.naver.com/itscholar/70043
B18: 공연과문화[공연,문화,축제,전시,공모전,취업,알바,창업,자격증] | C18: 113211 | D18: 2025. 1. 1. | F18: https://cafe.naver.com/moolpas/2593314 | G18: 1 | H18: https://cafe.naver.com/moolpas?iframe_url_utf8=%2FArticleRead.nhn%253Fclubid%3D10942133%2526articleid%3D2596120%2526menuid%3D51%2526boardtype%3DL
B19: IT인프라&네트워크 전문가 따라잡기 | F19: https://cafe.naver.com/neteg/279548 | G19: 13 | H19: https://cafe.naver.com/neteg/279548
B20: 알기사 | D20: 2025. 9. 1. | F20: https://cafe.naver.com/peopleofit/128901 | G20: 18 | H20: https://cafe.naver.com/peopleofit/128901
B21: 전산실 사람들 | D21: 2025. 9. 1. | F21: https://cafe.naver.com/itscholar/70043 | G21: 4 | H21: https://cafe.naver.com/peopleofit/128901
B22: 산업보안관리사 연합 | D22: 2025. 9. 1. | F22: https://cafe.naver.com/sanbosa/8291 | G22: 20 | H22: https://cafe.naver.com/sanbosa/8291
B23: 데이터 전문가 포럼 (DPForum) | C23: 191197 | D23: 2025. 1. 1. | F23: https://cafe.naver.com/sqlpd/90920 | G23: 90 | H23: https://cafe.naver.com/sqlpd/95296
B24: SW 개발자 취업&이직 정보공유 | D24: 2025. 9. 1. | F24: https://cafe.naver.com/workhub/24862 | G24: 15 | H24: https://cafe.naver.com/workhub/24862
B25: 갑취공 | C25: 194 | D25: 2025. 1. 1. | F25: https://cafe.naver.com/0eagle0/1037 | G25: 1 | H25: https://cafe.naver.com/0eagle0?iframe_url_utf8=%2FArticleRead.nhn%253Fclubid%3D15975313%2526articleid%3D1065%2526menuid%3D92%2526boardtype%3DL
B26: Artificial Intelligence Researchers | C26: 1723 | D26: 2025. 1. 1. | F26: https://cafe.naver.com/airesearchers/3306 | G26: 6 | H26: https://cafe.naver.com/airesearchers?iframe_url_utf8=%2FArticleRead.nhn%253Fclubid%3D30174813%2526articleid%3D3416%2526menuid%3D1%2526boardtype%3DL
B27: 창업지원센터 | C27: 3706 | D27: 2025. 1. 1. | F27: https://cafe.naver.com/alsoo/16066 | G27: 1 | H27: https://cafe.naver.com/alsoo?iframe_url_utf8=%2FArticleRead.nhn%253Fclubid%3D24000553%2526articleid%3D16094%2526menuid%3D41%2526boardtype%3DL
B28: MOTIVE - 공모전의 모든것 | C28: 105 | D28: 2025. 1. 1. | F28: https://cafe.naver.com/motive3be/5091 | G28: 2 | H28: https://cafe.naver.com/motive3be?iframe_url_utf8=%2FArticleRead.nhn%253Fclubid%3D30384112%2526articleid%3D5177%2526menuid%3D41%2526boardtype%3DL
B29: IT인프라&네트워크 전문가 따라잡기 | C29: 126905 | D29: 2025. 1. 1. | F29: https://cafe.naver.com/neteg/277098 | G29: 18 | H29: https://cafe.naver.com/neteg?iframe_url_utf8=%2FArticleRead.nhn%253Fclubid%3D10344409%2526articleid%3D279601%2526menuid%3D20%2526boardtype%3DL
B30: 아라공 | C30: 100693 | D30: 2025. 1. 1. | F30: https://cafe.naver.com/sdk800402/426874 | G30: 5 | H30: https://cafe.naver.com/sdk800402?iframe_url_utf8=%2FArticleRead.nhn%253Fclubid%3D15249111%2526articleid%3D429296%2526menuid%3D554%2526boardtype%3DL
B31: 스마트팜야학 | C31: 355 | D31: 2025. 1. 1. | F31: https://cafe.naver.com/sfyahak/30873 | G31: 2 | H31: https://cafe.naver.com/sfyahak?iframe_url_utf8=%2FArticleRead.nhn%253Fclubid%3D30611638%2526articleid%3D30893%2526menuid%3D1%2526boardtype%3DL
B32: 제약회사 취업전문 "파마메디잡" | C32: 59629 | D32: 2025. 9. 1. | F32: https://cafe.naver.com/1063216 | G32: 0 | H32: https://cafe.naver.com/1063216?iframe_url_utf8=%2FArticleRead.nhn%253Fclubid%3D10444735%2526articleid%3D379708%2526menuid%3D715%2526boardtype%3DL
B33: AI Startup community, AI 스타트업 커뮤니티 | C33: 3124 | D33: 2025. 9. 1. | F33: https://cafe.naver.com/2018startup/6399?art=ZXh0ZXJuYWwtc2VydmljZS1uYXZlci1zZWFyY2gtY2FmZS1wcg.eyJhbGciOiJIUzI1NiIsInR5cCI6IkpXVCJ9.eyJjYWZlVHlwZSI6IkNBRkVfVVJMIiwiY2FmZVVybCI6IjIwMThzdGFydHVwIiwiYXJ0aWNsZUlkIjo2Mzk5LCJpc3N1ZWRBdCI6MTc1MzY5MTYwMzQ5OH0.JBqJg4tOw3vDzs5tBlDTNYmST8r4srNS78FUR5mVv70 | G33: 1 | H33: https://cafe.naver.com/2018startup?iframe_url_utf8=%2FArticleRead.nhn%253Fclubid%3D29302637%2526articleid%3D6940%2526menuid%3D1%2526boardtype%3DL
B34: [마케팅형] 실무 디지컬마케팅 쏙쏙 배울 수 있는 카페 | C34: 632 | D34: 2025. 1. 1. | F34: https://cafe.naver.com/38005548/13514 | G34: 0 | H34: https://cafe.naver.com/38005548?iframe_url_utf8=%2FArticleRead.nhn%253Fclubid%3D30650226%2526articleid%3D13547%2526menuid%3D53%2526boardtype%3DL
B35: 인공지능LLM RAG Lanchain개발자모임 | C35: 1297 | D35: 2025. 1. 1. | F35: https://cafe.naver.com/aidev/997 | G35: 3 | H35: https://cafe.naver.com/aidev?iframe_url_utf8=%2FArticleRead.nhn%253Fclubid%3D30081332%2526articleid%3D1217%2526menuid%3D1%2526boardtype%3DL
B36: 인공지능과 교육 | C36: 31 | D36: 2025. 1. 1. | F36: https://cafe.naver.com/aied/162 | G36: 0 | H36: https://cafe.naver.com/aied?iframe_url_utf8=%2FArticleRead.nhn%253Fclubid%3D30008659%2526articleid%3D177%2526menuid%3D1%2526boardtype%3DL
... B52: 진로 정보 창체마을 | C52: 6912 | D52: 2025. 1. 1. | F52: https://cafe.naver.com/dreamdeo1/16036 | G52: 2 | H52: https://cafe.naver.com/dreamdeo1?iframe_url_utf8=%2FArticleRead.nhn%253Fclubid%3D29039495%2526articleid%3D16215%2526menuid%3D44%2526boardtype%3DL
B53: 사이드프로젝트 팀빌딩부터 스타트업까지, 사이프로 Sipro | C53: 2325 | D53: 기존 홍보채널 (경희대) | F53: https://cafe.naver.com/sidepro/2593
B54: IT취업 꿈꾸기 '아.이.꿈' | C54: 4626 | D54: 2025. 9. 1. | F54: https://cafe.naver.com/dreamingit/31772 | G54: 0 | H54: https://cafe.naver.com/f-e/cafes/21576449/menus/188?viewType=L
B55: 인공지능 | C55: 7 | D55: 2025. 1. 1. | F55: https://cafe.naver.com/ds344/57 | G55: 0 | H55: https://cafe.naver.com/ds344?iframe_url_utf8=%2FArticleRead.nhn%253Fclubid%3D24802777%2526articleid%3D72%2526menuid%3D5%2526boardtype%3DL
...

Sheet SNS그룹
A1: 게재일 | B1: 이름 | C1: 회원수 | D1: 등록일 | E1: 삭제일 | F1: 주소 | G1: 조회수 | H1: 결과 | I1: 메모
B2: AI Startup community, 인공지능 스타트업 커뮤니티 | C2: 30927 | D2: 2025. 1. 1. | F2: https://www.facebook.com/groups/aitutor21 | G2: 11 | H2: https://www.facebook.com/groups/aitutor21/posts/2382430348837053/
B3: AI Korea | C3: 29649 | D3: 2025. 1. 1. | F3: https://www.facebook.com/groups/AIKoreaOpen | I3: 김지원 문의중
B4: R Korea - KRUG(Korean R User Group) | C4: 8582 | D4: 2025. 1. 1. | F4: (20+) R Korea - KRUG(Korean R User Group) | Facebook | H4: https://www.facebook.com/groups/KoreaRUsers/?ref=share_group_link&rdid=bRmNqOscsK18T1Rq&share_url=https%3A%2F%2Fwww.facebook.com%2Fshare%2Fg%2F1Ap8VKTDBe | I4: 정우준 문의중
B5: 4차산업혁명포럼 | C5: 7517 | D5: 2025. 10. 13. | F5: https://www.facebook.com/groups/SIGFIR | H5: https://www.facebook.com/groups/1073935326009614?locale=ko_KR | I5: Yong Joon Moon 문의중
B6: PyData Korea | C6: 2803 | D6: 2025. 1. 1. | F6: https://www.facebook.com/groups/pydatakorea | I6: 관리자 컨택 불가
B7: 케라스 코리아 (Keras Korea) | C7: 10178 | D7: 2025. 1. 1. | F7: https://www.facebook.com/groups/KerasKorea | H7: https://www.facebook.com/groups/KerasKorea | I7: 황준원 문의중
B8: 데이터야놀자 - 노는 사람들 | C8: 4018 | D8: 2025. 1. 1. | F8: https://www.facebook.com/groups/318994605688517 | I8: 강민구 문의 중
B9: DevOps Korea | C9: 10327 | D9: 2025. 1. 1. | F9: https://www.facebook.com/groups/TeAnE/ | I9: 곽상용 문의중
B10: 한국데이터사이언스학회(Korean Association of Data Science) | C10: 10067 | D10: 2025. 1. 1. | F10: https://www.facebook.com/groups/datasci/ | I10: 이해인 문의중
B11: H-지식공유-Blockchain / AI / Cloud / Big data | C11: 310 | D11: 2025. 1. 1. | F11: https://www.facebook.com/groups/1614897388572764/ | I11: 가입대기중
B12: AI Art Metaverse | C12: 9428 | D12: 2025. 1. 1. | F12: https://www.facebook.com/groups/2874402582680461/ | I12: 승인대기중
B13: AI Trenz -by 오늘배움 | C13: 10832 | D13: 2025. 10. 13. | F13: https://www.facebook.com/groups/aitrenz/ | H13: https://www.facebook.com/groups/aitrenz/ | I13: Joo Banghyun 문의 중
B14: GenAI Korea | C14: 4241 | D14: 2025. 10. 13. | F14: https://www.facebook.com/groups/genaikorea/ | H14: https://www.facebook.com/groups/genaikorea/ | I14: AI관련행사 언제나 자유게재 가능, 김성완 문의중
B15: 모두의AI | C15: 1698 | D15: 2025. 1. 1. | F15: https://www.facebook.com/groups/moduai/ | I15: Goos Kim 문의중
B16: Korea Azure & AI Group | C16: 5354 | D16: 2025. 1. 1. | F16: https://www.facebook.com/groups/krazure/ | I16: 이철성 문의중
B17: AI Innovation | C17: 758 | D17: 2025. 1. 1. | F17: https://www.facebook.com/groups/1886103104972694/ | I17: Janghee Lee 문의 중
B18: Spatial AI KR | C18: 4025 | D18: 2025. 1. 1. | F18: https://www.facebook.com/groups/spatialaikr/ | I18: 이종훈 문의중
B19: AI 테크 포럼 | C19: 1463 | D19: 2025. 1. 1. | F19: https://www.facebook.com/groups/488633848223116/ | I19: 모바일테크 계정 문의중
B20: ETRI.AI | C20: 362 | D20: 2025. 1. 1. | F20: https://www.facebook.com/groups/2075201289192559/ | I20: 이상광 문의중
B21: AI 포럼/세미나/컨퍼런스/컨설팅 | C21: 3718 | D21: 2025. 1. 1. | F21: https://www.facebook.com/groups/929996580371773/ | I21: 비지니스 네트워크 만들기 문의중
B22: Generative AI - Vision & Graphics | C22: 3810 | D22: 2025. 1. 1. | F22: https://www.facebook.com/groups/847991005393886/ | I22: 김형섭 문의중
B23: AI와 함께하는 교육자 모임 | C23: 6567 | D23: 2025. 1. 1. | F23: https://www.facebook.com/groups/365415614171876/ | I23: 황유리 문의중
B24: XRGen AI | C24: 7054 | D24: 2025. 1. 1. | F24: https://www.facebook.com/groups/990479344355711/ | I24: Max Yoon 문의중
B25: VAAX(VR/AR/AI/XR) 트렌드 | C25: 1288 | D25: 2025. 1. 1. | F25: https://www.facebook.com/groups/AR.VR.MR.AI.trend/ | I25: Aiden 문의중
B26: AI 메타버스연구회 | C26: 757 | D26: 2025. 1. 1. | F26: https://www.facebook.com/groups/188483807345796/ | I26: 이건호 문의중
... B46: 데이터 분석 스터디 | C46: 3999 | D46: 2025. 1. 1. | F46: https://www.facebook.com/groups/dastudy/ | I46: DongHwan Yu 승인 완료
B47: 프론트엔드 스터디 그룹 | C47: 9427 | D47: 2025. 1. 1. | F47: https://www.facebook.com/groups/714671295358301/ | H47: https://www.facebook.com/groups/714671295358301/ | I47: 이웅모 문의중
B48: 나, 개발 한번 해보려고 그룹 | C48: 5462 | D48: 2025. 1. 1. | F48: https://www.facebook.com/groups/829865883847246/ | I48: 김인권 승인 완료
B49: 디지털 트랜스포메이션과 산업지능화 | C49: 549 | D49: 2025. 1. 1. | F49: https://www.facebook.com/groups/industrialdigitaltransformation/ | I49: 이상진 문의 중
B50: Little Big Data: 다양한 사람들의 데이터 사이언스 이야기 | C50: 1962 | D50: 2025. 1. 1. | F50: https://www.facebook.com/groups/littlebigdata/ | I50: Wooju Jeong 문의 중
B51: 스타트업 생태계 | C51: 2633 | D51: 2025. 1. 1. | F51: https://www.facebook.com/groups/207695952659035/ | I51: 강정문 문의 중
B52: 로봇활용코딩교육 | C52: 2471 | D52: 2025. 1. 1. | F52: https://www.facebook.com/groups/robotcodingedu/ | I52: 박광현 문의 중
B53: [IT & 보안] 세미나 & 교육 & 설문조사 | C53: 5222 | D53: 2025. 1. 1. | F53: https://www.facebook.com/groups/ITnSEC/ | I53: 정회원 문의 중
B54: 메타버스 사용자 커뮤니티 | C54: 5552 | D54: 2025. 1. 1. | F54: https://www.facebook.com/groups/vrheadsetgrp/ | I54: Sangho Lee 문의 중
B55: 파이썬 사랑방 with Django/React | C55: 4271 | D55: 2025. 1. 1. | F55: https://www.facebook.com/groups/askdjango/ | I55: 이진석 문의중
B56: AI CONTENTS | C56: 2278 | D56: 2025. 1. 1. | F56: https://www.facebook.com/groups/1111223483178711/ | I56: HoGyu Maeng 문의중
B57: 코리아그래픽스/XR/메타버스 | C57: 1358 | D57: 2025. 1. 1. | F57: https://www.facebook.com/groups/koreagraphics/ | I57: 박경수 문의 중
B58: 대한민국ESG메타버스포럼(KEMF) | C58: 249 | D58: 2025. 1. 1. | F58: https://www.facebook.com/groups/290169579766826/ | I58: 문형남 문의 중 | J58: 여기까지 문의 완료
B59: 노마드 세상 - 개발자, 디자이너, 기획자, 스타트업, 네트워킹, 코워킹, IT 트렌드 | C59: 458 | D59: 2025. 1. 1. | F59: https://www.facebook.com/groups/itnomad/ | I59: 김영환 문의 중
...

Sheet 커뮤니티
A1: 게재일 | B1: 이름 | C1: 회원수 | D1: 등록일 | E1: 삭제일 | F1: 주소 | G1: 조회수 | H1: 결과 | I1: 메모
B2: 이오플래닛 | D2: 2025. 9. 1. | F2: https://eopla.net/magazines/34726 | G2: 415 | H2: https://eopla.net/magazines/34726
B3: 디씨인사이드 프로그래밍 갤러리 | D3: 2025. 9. 1. | F3: https://gall.dcinside.com/board/view/?id=programming&no=2893079&page=1 | G3: 130 | H3: https://gall.dcinside.com/board/view/?id=programming&no=2893079&page=1
B4: 인디터웹 | D4: 2025. 9. 1. | F4: https://inditor.co.kr/bbs/board.php?bo_table=str&wr_id=358 | G4: 426 | H4: https://inditor.co.kr/bbs/board.php?bo_table=str&wr_id=358
B5: AI Dev - 인공지능 개발자 모임 | D5: 2025. 9. 1. | F5: http://aidev.co.kr/freeboard/11797 | G5: 279 | H5: https://aidev.co.kr/index.php?mid=freeboard&document_srl=16663
B6: AITUTOR21 | D6: 2025. 9. 1. | F6: http://aitutor21.com/bbs/board.php?bo_table=contest&wr_id=59 | G6: 624 | H6: https://aitutor21.com/contest/830
B7: 데브코리아 | D7: 2025. 9. 1. | F7: http://devkorea.co.kr/m01_seminar/1650
B8: 돌고넷 | D8: 2025. 9. 1. | F8: http://dolgo.net/tag/etc/question/767
B9: 꿈꾸는 개발자, DBA 커뮤니티 구루비 | D9: 2025. 9. 1. | F9: http://gurubee.net/article/86058
B10: 구루비 | D10: 2025. 9. 1. | F10: http://www.gurubee.net/article/90044
B11: Iamroot | D11: 2025. 9. 1. | F11: http://www.iamroot.org/xe/index.php?mid=Knowledge&document_srl=219077 | G11: 22 | H11: http://www.iamroot.org/xe/index.php?mid=Knowledge&document_srl=222816
B12: aigee | D12: 2025. 9. 1. | F12: https://aigee.ai/community/111916/%EC%A0%9C3%ED%9A%8C-%EB%84%A4%ED%8A%B8%EC%9B%8C%ED%81%AC-%EC%A7%80%EB%8A%A5%ED%99%94%EB%A5%BC-%EC%9C%84%ED%95%9C-%EC%9D%B8%EA%B3%B5%EC%A7%80%EB%8A%A5-%ED%95%B4%EC%BB%A4%ED%86%A4 | G12: 2 | H12: https://aigee.ai/community/113244/%EB%94%A5%ED%8E%98%EC%9D%B4%ED%81%AC-%EB%B2%94%EC%A3%84-%EB%8C%80%EC%9D%91%EC%9D%84-%EC%9C%84%ED%95%9C-AI-%ED%83%90%EC%A7%80-%EB%AA%A8%EB%8D%B8-%EA%B2%BD%EC%A7%84%EB%8C%80%ED%9A%8C-
B13: 커리어리 | D13: 2025. 9. 1. | F13: https://careerly.co.kr/comments/121148 | G13: 47 | H13: https://careerly.co.kr/comments/122750
B14: 뎁스노트 | D14: 2025. 9. 1. | F14: https://devsnote.com/writings/4058 | G14: 64 | H14: https://devsnote.com/@2555/post/9564
B15: 파이토치 | D15: 2025. 1. 1. | F15: https://discuss.pytorch.kr/t/topic/7241 | G15: 77 | H15: https://discuss.pytorch.kr/t/ai/7951
B16: 하모니케이알 | D16: 2025. 9. 1. | F16: https://hamonikr.org/index.php?mid=Free_Board&document_srl=144907 | G16: 104 | H16: https://hamonikr.org/index.php?mid=Free_Board&document_srl=145884
B17: 자바스크립트데브 | D17: 2025. 9. 1. | F17: https://jsdev.kr/t/2022-nh/6992
B18: 오키코리아 | D18: 2025. 9. 1. | F18: https://okky.kr/articles/1317344 | G18: 58 | H18: https://okky.kr/articles/1544519
B19: PHP스쿨 | D19: 2025. 9. 1. | F19: https://phpschool.com/gnuboard4/bbs/board.php?bo_table=adpr&wr_id=1427&page=&sfl=&stx=&sst=&sod=&spt=&page=&sca=%B1%E2%C5%B8
B20: 스프 | D20: 2025. 9. 1. | F20: https://soup.pw/projects/8595 | H20: https://soup.pw/projects/66407
B21: CodeIgniter(한국 사용자포럼) | D21: 2025. 9. 1. | F21: https://www.cikorea.net/bbs/view/ad?idx=24740&page=1&lists_style= | H21: https://www.cikorea.net/bbs/view/free?idx=28963&page=1&lists_style=
B22: LDS | D22: 2025. 9. 1. | F22: https://www.linuxdata.org/bbs/board.php?bo_table=info&wr_id=186&sfl=wr_subject&stx=2&sst=wr_datetime&sod=desc&sop=and&page=1&device=pc | G22: 371 | H22: https://www.linuxdata.org/bbs/board.php?bo_table=free&wr_id=411
D23: 2025. 9. 1. | F23: http://www.bizk.co.kr/board/new_read.php?sno=31511
B24: 창업코리아커뮤니티 | D24: 2025. 9. 1. | F24: https://www.dream.go.kr/changup/bbsCrd/communityDetail.do?seq=255&gubunType=A
B25: 대구창조경제혁신센터 | D25: 2025. 9. 1. | F25: https://startup.daegu.go.kr/index.do?menu_id=00002800&menu_link=/front/forum/forumMyList.do
B26: 넥스트유니콘 | D26: 2025. 9. 1. | F26: https://www.nextunicorn.kr/company/d3169c3cf8c3fb58

Sheet 블로그
A1: 게재일 | B1: 이름 | C1: 회원수 | D1: 등록일 | E1: 삭제일 | F1: 주소 | G1: 조회수 | H1: 결과 | I1: 메모
B2: 요즘것들 | D2: 2025. 1. 1. | F2: https://blog.naver.com/allforyoung | H2: https://blog.naver.com/allforyoung/224026707765
B3: 뎁스노트 - 메이캔 블로그 | D3: 2025. 1. 1. | F3: https://devsnote.com/%403101/post/9526 | G3: 61 | H3: https://devsnote.com/%403101/post/9526
B4: 뎁스노트 - 인공지능팩토리 블로그 | D4: 2025. 1. 1. | F4: https://devsnote.com/@2555/post/9176 | G4: 77 | H4: https://blog.naver.com/aifactory20/224041049679

Sheet 오픈단톡방
A1: 게재일 | B1: 이름 | C1: 회원수 | D1: 등록일 | E1: 삭제일 | F1: 주소 | G1: 조회수 | H1: 결과 | I1: 메모
B2: AI스타트업스터디커뮤니티_코드2969 | D2: 2025. 1. 1. | F2: https://open.kakao.com/o/gqnC0JM
B3: AI양자컴퓨팅스타트업스터디_코드2019 | D3: 2025. 1. 1. | F3: https://open.kakao.com/o/gSr7ISrd
B4: IT 톡 | D4: 2025. 1. 1. | F4: https://open.kakao.com/o/gRaittKg
B5: 개발자커뮤니티 | D5: 2025. 1. 1. | F5: https://open.kakao.com/o/gkERC3ce
B6: 게임개발101번지 | D6: 2025. 1. 1. | F6: https://open.kakao.com/o/gmRxmxv
B7: 겜 | D7: 2025. 1. 1. | F7: https://open.kakao.com/o/gxaZ4uA
B8: 데이터분석과 기계학습 | D8: 2025. 1. 1. | F8: https://open.kakao.com/o/gHY6rPp
B9: 데이터사이언스 취업/이직 | D9: 2025. 1. 1. | F9: https://open.kakao.com/o/g5Yqyctb
B10: 빅데이터분석기사 공모전/정보공유 | D10: 2025. 1. 1. | F10: https://open.kakao.com/o/gpc6BuM
B11: 인공지능/딥러닝 | D11: 2025. 1. 1. | F11: https://open.kakao.com/o/gkUvuUMc
B12: 전국에 있는 컴공&소웨생을 위한 커뮤니티 | D12: 2025. 1. 1. | F12: https://open.kakao.com/o/gysUutgf
B13: 정보보안기사 필기/실기 스터디 | D13: 2025. 1. 1. | F13: https://open.kakao.com/o/g6BaZXK
... B15: Deeplearning Playground(딥플) | D15: 2025. 1. 1. | F15: 비공개
B16: IT행사 알리미2 | C16: 652 | D16: 2025. 1. 1. | F16: https://open.kakao.com/o/ggFAj9C | I16: 자유 게시 가능
B17: 메타버스 AI 지식공유 그룹 | C17: 823 | D17: 2025. 1. 1. | F17: https://open.kakao.com/o/gghfDMee | I17: 라이프스킬즈 이동호 문의중
B18: 인공지능사이드프로젝트 | C18: 827 | D18: 2025. 1. 1. | F18: https://open.kakao.com/o/gqnC0JM | I18: 브라이언 문의중
B19: 파이썬 처음처럼 | C19: 707 | D19: 2025. 1. 1. | F19: https://open.kakao.com/o/gG6kgabb | I19: 황준원 문의중
B20: AI양자컴퓨팅스타트업커뮤니티 | C20: 168 | D20: 2025. 1. 1. | F20: https://open.kakao.com/o/gSr7ISrd | I20: 브라이언AI스타트업 커뮤니티 승인 완료
B21: AI프렌즈 | C21: 1467 | D21: 2025. 1. 1. | F21: https://open.kakao.com/o/ggewxi2 | I21: 유용균 문의중
B22: 바이블저니(성경 + AI 아트)- AI 코리아 커뮤니티 | C22: 408 | D22: 2025. 1. 1. | F22: https://open.kakao.com/o/g9OOSZef | I22: 노주나 문의중
B23: 인공지능 정보공유방 | C23: 1493 | D23: 2025. 1. 1. | F23: https://open.kakao.com/o/gNF5DQqd | I23: Yoshua 문의중

Sheet 대학교공문
A1: 게재일 | B1: 이름 | C1: 회원수 | D1: 등록일 | E1: 삭제일 | F1: 주소 | G1: 조회수 | H1: 결과 | I1: 메모
B2: 가톨릭대학교 | D2: 2025. 9. 1.
B3: 감리교신학대학교 | D3: 2025. 9. 1.
B4: 강릉영동대학교 | D4: 2025. 9. 1.
B5: 강릉원주대학교 | D5: 2025. 9. 1.
B6: 강서대학교 | D6: 2025. 9. 1.
B7: 강원관광대학교 | D7: 2025. 9. 1. | I7: 재확인 필요
B8: 강원대학교 IT대학 전기전자공학과 | D8: 2025. 9. 1.
B9: 거제대학교 | D9: 2025. 9. 1. | I9: 재확인 필요
B10: 건국대학교 | D10: 2025. 9. 1.
B11: 건양대학교 | D11: 2025. 9. 1.
B12: 경기과학기술대학교 | D12: 2025. 9. 1.
B13: 경남대학교 | D13: 2025. 9. 1.
B14: 경북대학교 IT대학 | D14: 2025. 9. 1.
B15: 경북전문대학교 | D15: 2025. 9. 1.
B16: 경상국립대학교 | D16: 2025. 9. 1.
B17: 경성대학교 | D17: 2025. 9. 1.
B18: 경운대학교 | D18: 2025. 9. 1.
B19: 경일대학교 | D19: 2025. 9. 1.
B20: 경찰대학 | D20: 2025. 9. 1.
B21: 계명문화대학교 | D21: 2025. 9. 1.
B22: 계원예술대학교 | D22: 2025. 9. 1.
B23: 고구려대학교 | D23: 2025. 9. 1. | I23: 재확인 필요
B24: 고신대학교 | D24: 2025. 9. 1.
B25: 과학기술연합대학원대학교 | D25: 2025. 9. 1.
B26: 광신대학교 | D26: 2025. 9. 1.
B27: 광양보건대학교 | D27: 2025. 9. 1. | I27: 재확인 필요
B28: 광주대학교 | D28: 2025. 9. 1.
B29: 광주보건대학교 | D29: 2025. 9. 1.
B30: 광주여자대학교 | D30: 2025. 9. 1.
B31: 국군간호사관학교 | D31: 2025. 9. 1.
B32: 국방대학교 | D32: 2025. 9. 1.
B33: 군산간호대학교 | D33: 2025. 9. 1.
B34: 군산대학교 산학협력단 | D34: 2025. 9. 1.
B35: 군장대학교 | D35: 2025. 9. 1.
B36: 극동대학교 | D36: 2025. 9. 1.
B37: 금오공과대학교 인공지능공학과 | D37: 2025. 9. 1. | I37: 재확인 필요
B38: 기독간호대학교 | D38: 2025. 9. 1.
B39: 김포대학교 | D39: 2025. 9. 1.
B40: 김해대학교 | D40: 2025. 9. 1.
...

Sheet 디스코드
A1: 게재일 | B1: 이름 | C1: 회원수 | D1: 등록일 | E1: 삭제일 | F1: 주소 | G1: 조회수 | H1: 결과 | I1: 메모
B2: Coding Lab | D2: 2025. 9. 1. | F2: https://discord.com/channels/687271752224735233/1111014379404656691
B3: Codo | D3: 2025. 9. 1. | F3: https://discord.com/channels/1198588439004725278/1221325600397066240
B4: DevBench 디벤치 | D4: 2025. 9. 1. | F4: https://discord.com/channels/645137556777992203/1086540757076299816
B5: 코딩의숲 | D5: 2025. 9. 1. | F5: https://discord.com/channels/783459957403156565/1286320367475888199

Sheet 대학원공문
A1: 게재일 | B1: 이름 | C1: 회원수 | D1: 등록일 | E1: 삭제일 | F1: 주소 | G1: 조회수 | H1: 결과 | I1: 메모
B2: 동국대학교 대학원 | D2: 2025. 9. 1.
B3: 경인교육대학교 교육전문대학원 과학교육전공 | D3: 2025. 9. 1.
B4: 국방부 국군조직 국방대학교 국방관리대학원 | D4: 2025. 9. 1. | I4: 재확인 필요
B5: 국제문화대학원대학교 | D5: 2025. 9. 1. | I5: 재확인 필요
B6: 대학 강원대학교 교육대학원 | D6: 2025. 9. 1.
B7: 대학 서울과학기술대학교 IT정책전문대학원 | D7: 2025. 9. 1.
B8: 대학 서울과학기술대학교 산업대학원 | D8: 2025. 9. 1.
B9: 대학 서울과학기술대학교 일반대학원 | D9: 2025. 9. 1.
B10: 서울과학기술대학교 국방융합과학대학원 | D10: 2025. 9. 1.
B11: 서울대학교 대학원 대학원 | D11: 2025. 9. 1.
B12: 서울특별시 서울시립대학교 과학기술대학원 | D12: 2025. 9. 1.
B13: 순천대학교 대학원 | D13: 2025. 9. 1.
B14: 강원대학교 삼척캠퍼스 일반대학원 수소에너지융합공학과 | D14: 2025. 9. 1.
B15: 경북대학교 경영대학원 | D15: 2025. 9. 1.
B16: 경북대학교 과학기술대학원 | D16: 2025. 9. 1.
B17: 경북대학교 교육대학원 | D17: 2025. 9. 1.
... B31: 대학 강원대학교 산업대학원 | D31: 2025. 9. 1.
B32: 대학 개신대학원대학교 | D32: 2025. 9. 1. | I32: 재확인 필요
B33: 대학 건신대학원대학교 | D33: 2025. 9. 1. | I33: 재확인 필요
B34: 대학 경안신학대학원대학교 | D34: 2025. 9. 1.
B35: 대학 경인교육대학교 교육전문대학원 | D35: 2025. 9. 1. | I35: 재확인 필요
B36: 대학 구세군사관대학원대학교 | D36: 2025. 9. 1.
B37: 대학 국제뇌교육종합대학원대학교 | D37: 2025. 9. 1.
B38: 대학 국제법률경영대학원대학교 | D38: 2025. 9. 1.
B39: 대학 국제암대학원대학교 | D39: 2025. 9. 1.
B40: 대학 국제영어대학원대학교 | D40: 2025. 9. 1.
B41: 대학 금오공과대학교 교육대학원 | D41: 2025. 9. 1.
B42: 대학 금오공과대학교 대학원 | D42: 2025. 9. 1.
B43: 대학 금오공과대학교 산업대학원 | D43: 2025. 9. 1.
B44: 대학 능인대학원대학교 | D44: 2025. 9. 1.
B45: 대학 대한신학대학원대학교 | D45: 2025. 9. 1.
B46: 대학 서울과학기술대학교 일반대학원 TESOL학과 | D46: 2025. 9. 1. | I46: 재확인 필요
B47: 대학 서울과학기술대학교 일반대학원 AI경영학과 | D47: 2025. 9. 1.
B48: 대학 서울과학종합대학원대학교 | D48: 2025. 9. 1. | I48: 재확인 필요
B49: 대학 서울미디어대학원대학교 | D49: 2025. 9. 1.
B50: 대학 서울벤처대학원대학교 | D50: 2025. 9. 1.
B51: 대학 서울외국어대학원대학교 | D51: 2025. 9. 1.
B52: 대학 성산효대학원대학교 | D52: 2025. 9. 1.
B53: 대학 순천대학교 대학원 고분자화학화학공학과 | D53: 2025. 9. 1.
...

Sheet 고등학교공문
A1: 게재일 | B1: 이름 | C1: 회원수 | D1: 등록일 | E1: 삭제일 | F1: 주소 | G1: 조회수 | H1: 결과 | I1: 메모
B2: 영등포고등학교 | D2: 2025. 9. 1.

Sheet 기관공문
A1: 게재일 | B1: 이름 | C1: 회원수 | D1: 등록일 | E1: 삭제일 | F1: 주소 | G1: 조회수 | H1: 결과 | I1: 메모
B2: 구미전자정보기술원 | D2: 2025. 1. 1.
B3: 한국환경산업기술원 | D3: 2025. 1. 1.

Sheet DM-학회
A1: 게재일 | B1: 이름 | C1: 회원수 | D1: 등록일 | E1: 삭제일 | F1: 이메일 주소 | G1: 조회수 | H1: 홈페이지 주소 | I1: 메모
B2: (사)한국인공지능학회 | D2: 45658 | F2: kaia@aiassociation.kr
B3: (사)한국지능시스템학회 | D3: 45658 | F3: kfis@fuzzy.or.kr
B4: (사)한국지능정보시스템학회 | D4: 45658 | F4: office@kiiss.or.kr
B5: 대한의료인공지능학회 | D5: 45658 | F5: office@kosaim.org
B6: 대한전자공학회 | D6: 45658 | F6: ieie@theieie.org
B7: 한국인공지능교육학회 | D7: 45658 | F7: aiedorkr@gmail.com
B8: 한국정보과학회 | D8: 45658 | F8: kiise@kiise.or.kr
B9: 한국정보과학회 인공지능 소사이어티 | D9: 45658 | F9: hrbyun@yonsei.ac.kr
B10: (사)한국빅데이터학회 | D10: 45658 | F10: bigdata@kbigdata.kr

Sheet DM-협회
A1: 게재일 | B1: 이름 | C1: 회원수 | D1: 등록일 | E1: 삭제일 | F1: 이메일 주소 | G1: 조회수 | H1: 홈페이지 주소 | I1: 전화번호 | J1: 결과
B2: 대덕 이노폴리스벤처협회 | D2: 45658 | F2: chae@diva.or.kr | I2: 042-867-9700 | J2: https://www.diva.or.kr/sub040102/view/id/998#u
B3: 벤처기업협회 | D3: 45658 | F3: yjh8867@kova.or.kr | I3: 02-6331-7101 / 02-6331-7004 | J3: https://venture.or.kr/#/home/bizNotice/h020102/8556/1
B4: 지능정보산업협회 | D4: 45658 | F4: aiia@k-ai.or.kr | I4: T/ 02 6265 8750, F/ 02 6265 8766 | J4: https://www.k-ai.or.kr/kr/information/notice.php?bgu=view&bbs_data=aWR4PTE1NjUmc3RhcnRQYWdlPSZsaXN0Tm89JnRhYmxlPSZjb2RlPXRhYjRfYzEmc2VhcmNoX2l0ZW09JnNlYXJjaF9vcmRlcj0=%7C%7C
B5: 한국인공지능협회 | D5: 45658 | F5: info@koraia.org | I5: T/ 02-713-4800, F/ 0504-266-5568 | J5: koraia.org/default/mp6/mp6_sub10.php?com_board_basic=read_form&com_board_idx=167&sub=10&&com_board_search_code=&com_board_search_value1=&com_board_search_value2=&com_board_page=1&&com_board_id=6&&com_board_id=6
B6: IT여성기업인협회 | D6: 45658 | F6: kibwa@kibwa.org | H6: http://www.kibwa.org | I6: 02-6956-9952 | J6: http://www.kibwa.org/board/board_view?code=support&no=490
B7: 대전창조경제혁신센터 | D7: 45658 | F7: daejeon@ccei.kr | I7: 042-385-0666 | J7: ccei.creativekorea.or.kr/daejeon/custom/notice_view.do?no=22846&rnum=1077&kind=undefined&sPtime=undefined
B8: 전북 창업경제 혁신센터 | D8: 45658 | I8: 063-220-8900 | J8: https://jbci.or.kr/s2_1_view.html?id=2240&offset=20&findvalue=&search=&gubun=%EC%A0%84%EC%B2%B4&step1=&step2=&step3=&step4=
B9: INNOPOLIS 연구개발특구 진흥재단 | D9: 45658 | I9: 042-865-8800 | J9: https://www.innopolis.or.kr/board/view?pageNum=1&rowCnt=10&no1=2433&linkId=45951&menuId=MENU00318&schType=0&schText=&boardStyle=&categoryId=&continent=&country=
B10: 벤처스퀘어 | D10: 45658 | J10: https://www.venturesquare.net/announcement/841006
B11: 경기벤처기업협회 | D11: 45658 | F11: giva21@giva.or.kr | I11: 031-259-7240
B12: 경남벤처기업협회 | D12: 45658 | F12: kyungnam@kova.or.kr | I12: 055-238-9100
B13: 광주전남 벤처기업협회 | D13: 45658 | F13: bemex@naver.com | I13: 062-236-0080
B14: 부산벤처기업협회 | D14: 45658 | F14: hellobuva@naver.com | I14: 051-343-0109
B15: 부천벤처협회 | D15: 45658 | F15: b-venture@hanmail.net
B16: 빅데이터 정보보호융합기술협회 | D16: 45658 | F16: sneakerss@saeoll.com | I16: 02-554-3155
B17: 선한인공지능연구소 | D17: 45658 | F17: edu@goodai.kr | I17: 055-741-3152
B18: 시니어벤처협회 | D18: 45658 | F18: info@sva.or.kr | I18: 02-415-2188
B19: 시흥시벤처기업협회 | D19: 45658 | F19: tycho@arin.co.kr | I19: 031-404-3522
B20: 인공지능벤처협회 | D20: 45658 | F20: ai@kaiv.org | I20: -
B21: 인천벤처기업협회 | D21: 45658 | F21: pcw8688@inva.or.kr | I21: 032-817-2900
B22: 중소벤처기업협회 | D22: 45658 | F22: msa@msa.or.kr | I22: (대) 02-2039-2113 / 기술창업센터 070-5214-0195
B23: 충남벤처협회 | D23: 45658 | F23: cvapeople@gmail.com | I23: 041-589-0370
B24: 한국가상증강현실산업협회 | D24: 45658 | F24: kvra@kvra.kr | I24: 02-2132-1260
B25: 한국여성벤처협회 | D25: 45658 | F25: kovwa@kovwa.or.kr | I25: 02-3440-7460
B26: 한국인공지능기업협회 | D26: 45658 | F26: kaiedu@gmail.com | I26: 02-6953-8053
B27: 한국인공지능윤리협회 | D27: 45658 | F27: kaiea@kaiea.org | I27: 02-701-1237
... B37: 한국IT비즈니스진흥협회 | D37: 45658 | F37: koipa@koipa.or.kr | I37: 02-556-2024
B38: 인공지능교사협회 | D38: 45658 | F38: aiedteacher@gmail.com
B39: 울산창조경제혁신센터 | D39: 45658 | F39: ulsan_ccei@ccei.kr | I39: 052-222-9120
B40: 대구창조경제혁신 | D40: 45658 | F40: changup@ccei.kr | I40: 053-759-6380
B41: 충남창조경제혁신센터 | D41: 45658 | F41: yuhy@ccei.kr, chungnam@ccei.kr | I41: 041-536-7888
B42: 경기창조경제혁신 | D42: 45658 | F42: gccei_info@ccei.kr | I42: 031-8016-1102
B43: 서울창조경제혁신센터 | D43: 45658 | F43: ysjun@ccei.kr | I43: 02-723-9100
B44: 경북창조경제혁신센터 | D44: 45658 | F44: kmy3588@ccei.kr | I44: 054-470-2614
B45: 케이뷰티학회 | D45: 45658 | F45: shuuung@naver.com
B46: 한국소프트웨어산업협회 | D46: 45658 | F46: kosa@sw.or.kr | I46: 02-2188-6900
B47: 부산창조경제혁신센터 | D47: 45658 | F47: ymlee1106@ccei.kr
B48: 전라북도 창원정보 온라인 서비스 | D48: 45658 | F48: mj96@ccei.kr | J48: https://jbci.or.kr/s2_1_view.html?id=2240&offset=20&findvalue=&search=&gubun=%EC%A0%84%EC%B2%B4&step1=&step2=&step3=&step4=

Sheet DM-대학
A1: 게재일 | B1: 이름 | C1: 회원수 | D1: 등록일 | E1: 삭제일 | F1: 이메일 주소 | G1: 조회수 | H1: 결과 | I1: 메모
B2: 국민대학교 소프트웨어융합대학 | D2: 45658 | F2: sw2017@kookmin.ac.kr | I2: 대학교
B3: 공주대학교 컴퓨터공학과 | D3: 45658 | F3: hak315@kongju.ac.kr | I3: 대학교
B4: 경북대학교 IT대학 컴퓨터학부 | D4: 45658 | F4: imgreen@knu.ac.kr | I4: 대학교
B5: 고려대학교 전자및정보공학과 | D5: 45658 | F5: tec006@korea.ac.kr | I5: 대학교
B6: 아주대학교 정보통신대학 | D6: 45658 | F6: ijs0430@ajou.ac.kr | I6: 대학교
B7: 부산대학교 | D7: 45658 | F7: student@pusan.ac.kr | I7: 대학교
B8: 서강대학교 일반대학원 | D8: 45658 | F8: gradsch@sogang.ac.kr | I8: 인공지능대학원
B9: 창원대학교 컴퓨터공학과 | D9: 45658 | F9: computer@changwon.ac.kr | I9: 대학교
B10: 중원대학교 | D10: 45658 | F10: job@jwu.ac.kr | I10: 대학교
B11: 중부대학교 게임소프트웨어전공 | D11: 45658 | F11: gksch98@joongbu.ac.kr | I11: 대학교
B12: 신경대학교 컴퓨터학과 | D12: 45658 | F12: job@sgu.ac.kr | I12: 대학교
B13: 광주여자대학교 AI융합학과 | D13: 45658 | F13: support@kwu.ac.kr | I13: 대학교
... B78: 대구경북과학기술원 | D78: 45658 | F78: youmin9172@dgist.ac.kr | I78: 대학교
B79: 대구경북과학기술원 | D79: 45658 | E79: 45931 | F79: ssc@dgist.ac.kr | I79: 대학교
B80: 충북대학교 산학협력단 | D80: 45658 | F80: sanhak@cbnu.ac.kr | I80: 대학교
B81: 부산대학교 산업공학과 | D81: 45658 | F81: iepnu@pusan.ac.kr | I81: 대학교
B82: 한국항공대학교 소프트웨어학과 | D82: 45658 | F82: yakim@kau.ac.kr | I82: SW중심대학
B83: 동서대학교 sw중심대학산업단 | D83: 45658 | F83: hmshin@g.dongseo.ac.kr | I83: SW중심대학
B84: 한림대학교 sw중심대학산업단 | D84: 45658 | F84: hlsw@hallym.ac.kr | I84: SW중심대학
B85: 한양대학교 공과대학 | D85: 45658 | F85: help@hanyang.ac.kr | I85: 대학교
B86: 국민대학교 창의공과대학 전자공학부 | D86: 45658 | F86: sjybn@kookmin.ac.kr | I86: 대학교
B87: 건양대학교 | D87: 45658 | F87: jjuon@konyang.ac.kr | I87: 대학교
B88: 국민대학교 산학협력단 | D88: 45658 | F88: ajmen@kookmin.ac.kr | I88: 대학교
B89: 국민대학교 자동차공학 전문대학원 | D89: 45658 | F89: rijoo77@kookmin.ac.kr | I89: 대학교
B90: 조선대학교 | D90: 45658 | F90: min0608@chosun.ac.kr | I90: 대학교
B91: 국민대학교 산학협력단 | D91: 45658 | F91: iijjnn@kookmin.ac.kr | I91: 대학교
... B136: 공주대학교 컴퓨터공학과 | D136: 45658 | F136: okok@kongju.ac.kr | I136: 대학교
B137: KC대학교 빅데이터경영학과 | D137: 45658 | E137: 45931 | F137: g2bn@kcu.ac.kr | I137: 대학교
B138: 한신대학교 응용소프트웨어공학과 | D138: 45658 | F138: fff104578@hs.ac.kr | I138: 대학교
B139: 서울시립대학교 공과대학 | D139: 45658 | E139: 45931 | F139: engineer@uos.ac.kr | I139: 대학교
B140: 부산디지털대학교 컴퓨터공학과 | D140: 45658 | F140: lej4515@naver.com | I140: 대학교
B141: 한양대학교 컴퓨터·소프트웨어학과 | D141: 45658 | F141: leeyj82@hanyang.ac.kr | I141: 대학교
B142: 단국대학교 컴퓨터공학과 | D142: 45658 | F142: seungji@dankook.ac.kr | I142: 대학교
B143: 동신대학교 컴퓨터공학과 | D143: 45658 | F143: shadowlhi@nate.com | I143: 대학교
B144: 성균관대학교 컴퓨터공학과 | D144: 45658 | F144: shin32@skku.edu | I144: 대학교
B145: 세종사이버대학교 컴퓨터ai공학과 | D145: 45658 | F145: sjcuit@sjcu.ac.kr | I145: 대학교
B146: 순천향대학교 컴퓨터소프트웨어공학과 | D146: 45658 | F146: dyoung.kim@sch.ac.kr | I146: 대학교
B147: 세종대학교 데이터사이언스학과 | D147: 45658 | F147: dsdpt@sejong.ac.kr | I147: 대학교
B148: 영남대학교 컴퓨터공학과 | D148: 45658 | F148: dlthals0319@yu.ac.kr | I148: 대학교
...

Sheet 옥외광고-대학
A1: 게재일 | B1: 이름 | C1: 인원 | D1: 등록일 | E1: 삭제일 | F1: 본분교 | G1: 학제 | H1: 지역 | I1: 설립구분 | J1: 주소 | K1: 우편번호 | L1: 학교명(영문) | M1: 학교홈페이지 | N1: 총장명 | O1: 학교대표 번호 | P1: 학교대표 팩스번호
B2: 국립강릉원주대학교 | D2: 2025. 12. 4. | F2: 본교 | G2: 대학교 | H2: 강원 | I2: 국립 | J2: 강원특별자치도 강릉시 죽헌길 7 | K2: 25457 | L2: Gangneung Wonju National University | M2: www.gwnu.ac.kr | N2: 박덕영 | O2: 033-642-7001 | P2: 033-643-7110
B3: 국립강릉원주대학교 | D3: 2025. 12. 4. | F3: 제2캠퍼스 | G3: 대학교 | H3: 강원 | I3: 국립 | J3: 강원특별자치도 원주시 흥업면 남원로 150 | K3: 26403 | L3: Gangneung Wonju National University | M3: www.gwnu.ac.kr | N3: 박덕영 | O3: 033-760-8020 | P3: 033-760-8029
B4: 강원대학교 | D4: 2025. 12. 4. | F4: 본교 | G4: 대학교 | H4: 강원 | I4: 국립 | J4: 강원특별자치도 춘천시 강원대학길 1 | K4: 24341 | L4: Kangwon National University | M4: www.kangwon.ac.kr/ | N4: 정재연 | O4: 033-250-6114 | P4: 033-251-9556
B5: 강원대학교 | D5: 2025. 12. 4. | F5: 제2캠퍼스 | G5: 대학교 | H5: 강원 | I5: 국립 | J5: 강원특별자치도 삼척시 중앙로 346 | K5: 25913 | L5: Kangwon National University | M5: www.kangwon.ac.kr/ | N5: 정재연 | O5: 033-570-6114 | P5: 033-572-8620
B6: 경북대학교 | D6: 2025. 12. 4. | F6: 본교 | G6: 대학교 | H6: 대구 | I6: 국립 | J6: 대구광역시 북구 대학로 80 | K6: 41566 | L6: Kyungpook National University | M6: www.knu.ac.kr | N6: 허영우 | O6: 053-950-5114 | P6: 053-950-2149
B7: 경상국립대학교 | D7: 2025. 12. 4. | F7: 본교 | G7: 대학교 | H7: 경남 | I7: 국립 | J7: 경상남도 진주시 진주대로 501 | K7: 52828 | L7: Gyeongsang National University | M7: www.gnu.ac.kr | N7: 권진회 | O7: 055-772-1114 | P7: 055-772-0359
B8: 국립공주대학교 | D8: 2025. 12. 4. | F8: 본교 | G8: 대학교 | H8: 충남 | I8: 국립 | J8: 충청남도 공주시 공주대학로 56 | K8: 32588 | L8: Kongju National University | M8: www.kongju.ac.kr | N8: 임경호 | O8: 041-850-8114 | P8: 041-850-8019
B9: 국립군산대학교 | D9: 2025. 12. 4. | F9: 본교 | G9: 대학교 | H9: 전북 | I9: 국립 | J9: 전북특별자치도 군산시 대학로 558 | K9: 54150 | L9: Kunsan National University | M9: www.kunsan.ac.kr | N9: 이장호 | O9: 063-469-4114 | P9: 063-469-5334
B10: 국립금오공과대학교 | D10: 2025. 12. 4. | F10: 본교 | G10: 대학교 | H10: 경북 | I10: 국립 | J10: 경상북도 구미시 대학로 61 | K10: 39177 | L10: Kumoh National Institute Of Technology | M10: www.kumoh.ac.kr | N10: 곽호상 | O10: 054-478-7114 | P10: 054-478-7100
B11: 국립목포대학교 | D11: 2025. 12. 4. | F11: 본교 | G11: 대학교 | H11: 전남 | I11: 국립 | J11: 전라남도 무안군 청계면 영산로 1666 | K11: 58554 | L11: Mokpo National University | M11: www.mokpo.ac.kr | N11: 송하철 | O11: 061-450-2114 | P11: 061-452-4793
B12: 국립목포해양대학교 | D12: 2025. 12. 4. | F12: 본교 | G12: 대학교 | H12: 전남 | I12: 국립 | J12: 전라남도 목포시 해양대학로 91 | K12: 58628 | L12: Mokpo National Maritime University | M12: www.mmu.ac.kr | N12: 한원희 | O12: 061-240-7114 | P12: 061-242-5176
B13: 국립부경대학교 | D13: 2025. 12. 4. | F13: 본교 | G13: 대학교 | H13: 부산 | I13: 국립 | J13: 부산광역시 남구 용소로 45 | K13: 48513 | L13: Pukyong National University | M13: www.pknu.ac.kr | N13: 배상훈 | O13: 051-629-4114 | P13: 051-629-5089
... B229: 국립창원대학교(남해캠퍼스) | D229: 2025. 12. 4. | F229: 제3캠퍼스 | G229: 대학교 | H229: 경남 | I229: 국립 | J229: 경상남도 남해군 남해읍 화전로78번길 30 | K229: 52422 | L229: Changwon National University | M229: www.changwon.ac.kr | N229: 박민원 | O229: 055-254-2400 | P229: 055-254-2419
B230: 국립목포대학교(담양캠퍼스) | D230: 2025. 12. 4. | F230: 제2캠퍼스 | G230: 대학교 | H230: 전남 | I230: 국립 | J230: 전라남도 담양군 담양읍 죽녹원로 152 | K230: 57337 | L230: Mokpo National University | N230: 송하철 | O230: 614502114 | P230: 614524793
B231: 호원대학교 | D231: 2025. 12. 4. | F231: 본교 | G231: 산업대학 | H231: 전북 | I231: 사립 | J231: 전북특별자치도 군산시 임피면 호원대3길 64 | K231: 54058 | L231: Howon University | M231: www.howon.ac.kr | N231: 강희성 | O231: 063-450-7114 | P231: 063-450-7777
B232: 청운대학교 | D232: 2025. 12. 4. | F232: 본교 | G232: 산업대학 | H232: 충남 | I232: 사립 | J232: 충청남도 홍성군 홍성읍 대학길 25 | K232: 32244 | L232: Chungwoon University | M232: www.chungwoon.ac.kr | N232: 정윤 | O232: 041-630-3114 | P232: 041-634-8700

Sheet 옥외광고-출연연NST
A1: 게재일 | B1: 이름 | C1: 인원 | D1: 등록일 | E1: 삭제일 | F1: 주소 | G1: 담당연락처 | H1: 언론/과학문화 담당 | I1: 대표전화
B2: 한국과학기술연구원(KIST) | D2: 2025. 12. 4. | F2: 서울특별시 성북구 화랑로 14길 5 | G2: 02-958-6406 | H2: 송우진 | I2: 02-958-5114
B3: 국가녹색기술연구소 | D3: 2025. 12. 4. | F3: 서울특별시 영등포구 여의나루로 60 여의도포스트타워 14층 | G3: 02-3393-3988 | H3: 오상진 | I3: 02-3393-3900
B4: 한국기초과학지원연구원(KBSI) | D4: 2025. 12. 4. | F4: 대전광역시 유성구 과학로 169-148 | G4: 042-865-3942 | H4: 유윤지 | I4: 042-865-3500
B5: 한국생명공학연구원(KRIBB) | D5: 2025. 12. 4. | F5: 대전광역시 유성구 과학로 125 | G5: 042-860-4734 | H5: 권미자 | I5: 042-860-4114
B6: 한국과학기술정보연구원(KISTI) | D6: 2025. 12. 4. | F6: 대전광역시 유성구 대학로 245 | G6: 042-869-0864 | H6: 박준수 | I6: 042-869-1234
B7: 한국한의학연구원 | D7: 2025. 12. 4. | F7: 대전광역시 유성구 유성대로 1672 | G7: 042-868-9656 | H7: 김백선 | I7: 042-861-1994
B8: 한국생산기술연구원 | D8: 2025. 12. 4. | F8: 충남 천안시 서북구 입장면 양대기로길 89 한국생산기술연구원 | G8: 041-589-8039 | H8: 유진하 | I8: 041-589-8114
B9: 한국전자통신연구원(ETRI) | D9: 2025. 12. 4. | F9: 대전광역시 유성구 가정로 218 | G9: 042-860-0681 | H9: 김민규 | I9: 042-860-6114
B10: ETRI 국가보안기술연구소 | D10: 2025. 12. 4. | F10: 대전 유성구 유성대로 1559 | G10: 042-870-4912 | H10: 배근수 | I10: 042-870-2114
B11: 한국건설기술연구원(KICT) | D11: 2025. 12. 4. | F11: 경기도 고양시 일산서구 고양대로 283 | G11: 031-995-0965 | H11: 함연희 | I11: 031-910-0114
B12: 한국철도기술연구원 | D12: 2025. 12. 4. | F12: 경기 의왕시 철도박물관로 176 철도기술연구원 | G12: 031-460-5186 | H12: 김진호 | I12: 031-460-5000
B13: 한국표준과학연구원 | D13: 2025. 12. 4. | F13: 대전 유성구 가정로 267 한국표준과학연구원 | G13: 042-868-5596 | H13: 이윤희 | I13: 042-868-5114
... B24: 한국핵융합에너지연구원 | D24: 2025. 12. 4. | F24: 대전 유성구 과학로 169-148 한국핵융합에너지연구원 | G24: 042-879-5542 | H24: 김중광 | I24: 042-879-6000

Sheet 옥외광고-협력기관
A1: 게재일 | B1: 이름 | C1: 인원 | D1: 등록일 | E1: 삭제일 | F1: 주소 | G1: 담당연락처 | H1: 언론/과학문화 담당 | I1: 대표전화
B2: 한국과학 AI포럼 | D2: 2025. 12. 4. | F2: 서울 관악구 관악로 1 서울대학교 자연과학대학 화학부 502동 223호 | H2: 석차옥 | I2: 02-880-9197
B3: AIFrenz학회 | D3: 2025. 12. 4. | F3: 대전광역시 유성구 대덕대로 593 대덕테크비즈센터 B1-11 | H3: 유용균 | I3: 042-863-1016
B4: LG AI연구원 | D4: 2025. 12. 4. | F4: 서울시 강서구 마곡중앙로 150 | H4: 임우형
B5: NHN 클라우드 | D5: 2025. 12. 4. | F5: 경기도 성남시 분당구 대왕판교로645번길 16, NHN 플레이뮤지엄 4, 7층 | H5: 김동훈
B6: 한국과학기술연구원(KIST) | D6: 2025. 12. 4. | F6: 서울특별시 성북구 화랑로 14길 5 | G6: 02-958-6406 | H6: 송우진 | I6: 02-958-5114
B7: 한국전자통신연구원(ETRI) | D7: 2025. 12. 4. | F7: 대전광역시 유성구 가정로 218 | G7: 042-860-0681 | H7: 김민규 | I7: 042-860-6114
B8: 한국과학기술정보연구원(KISTI) | D8: 2025. 12. 4. | F8: 대전광역시 유성구 대학로 245 | G8: 042-869-0864 | H8: 박준수 | I8: 042-869-1234

Sheet 퍼포먼스
A1: 게재일 | B1: 이름 | C1: 회원수 | D1: 등록일 | E1: 삭제일 | F1: 주소 | G1: 조회수 | H1: 결과 | I1: 메모
B2: 메타(페북,인스타) | D2: 2025. 9. 1. | G2: 149978 | H2: https://www.instagram.com/p/DPKwxpsDI6f/#advertiser

Sheet 이벤트사이트
A1: 게재일 | B1: 이름 | C1: 회원수 | D1: 등록일 | E1: 삭제일 | F1: 주소 | G1: 조회수 | H1: 결과 | I1: 메모
B2: 슈퍼투데이 | D2: 45658 | F2: https://www.suto.co.kr/ | I2: 이벤트 홍보가능
B3: 이벤트포유 | D3: 45658 | F3: https://e4u.kr/bbs/board.php?bo_table=gongmo&wr_id=123 | I3: 무료 이벤트 공모전 홍보가능
